Workbook

Sheet Front Page
A1: Author:
A2: Steelux
A4: Issues:
A5: Machine naming conventions: Chemical Reactor, Large Chemical Reactor or LCR? Mixer, Industrial Mixing Machine or IMM?
A6: There's a difference between singles and multis, and both need to be easily identifiable, but not all acronyms are known
A7: Whether it's a single or a multi, it has to be clear which one it is

Sheet Item List
A1: Item | B1: GT Tier Number | C1: Importance | D1: Rarity
A2: 1,2-Dimethylbenzene | B2: 1 | C2: 3 | D2: 2
A3: 1,3-Dimethylbenzene | B3: 1 | C3: 3 | D3: 2
A4: 1,4-Dimethylbenzene | B4: 1 | C4: 3 | D4: 2
A5: Acetic Acid | B5: 1 | C5: 4 | D5: 2
A6: Acetone | B6: 1 | C6: 4 | D6: 2
A7: Acidic Iridium Solution | B7: 1 | C7: 3 | D7: 2
A8: Acidic Osmium Solution | B8: 1 | C8: 3 | D8: 2
A9: Aluminium Ingot | B9: 1 | C9: 3 | D9: 2
A10: Aluminium Foil | B10: 1 | C10: 3 | D10: 2
A11: Aluminium Frame Box | B11: 1 | C11: 3 | D11: 2
A12: Ammonia | B12: 3 | C12: 5 | D12: 2
A13: Ammonium Bifluoride | B13: 1 | C13: 3 | D13: 2
... A258: Sulfur Dust | B258: 1 | C258: 3 | D258: 2

Sheet Machine List
A1: Machine | B1: Parallel Count | C1: Speed Modifier | D1: Energy Modifier | E1: Multi Type | F1: Single Energy Hatch | G1: Needs to Craft | H1: Starting Cost | I1: Machine Cost
A2: Alloy Blast Smelter | B2: 1 | C2: 1 | D2: 1 | E2: Multi | F2: No | G2: T2 Rocket | H2: =IF(G2="Tier", "Tier", IFNA(VLOOKUP(G2,'Machine Helper Sheet'!$B$2:$D$16,3,FALSE), IF(ISNUMBER(VLOOKUP(G2,$A$2:$I$200,9,FALSE)), VLOOKUP(G2,$A$2:$I$200,8,FALSE)+VLOOKUP(G2,$A$2:$I$200,9,FALSE), 0 ) ) ) -> 1105511 | I2: 300000
A3: Alloy Smelter | B3: 1 | C3: 1 | D3: 1 | E3: Single | F3: No | G3: Tier | H3: =IF(G3="Tier", "Tier", IFNA(VLOOKUP(G3,'Machine Helper Sheet'!$B$2:$D$16,3,FALSE), IF(ISNUMBER(VLOOKUP(G3,$A$2:$I$200,9,FALSE)), VLOOKUP(G3,$A$2:$I$200,8,FALSE)+VLOOKUP(G3,$A$2:$I$200,9,FALSE), 0 ) ) ) -> Tier | I3: 1T
A4: Arc Furnace | B4: 1 | C4: 1 | D4: 1 | E4: Single | F4: No | G4: Tier | H4: =IF(G4="Tier", "Tier", IFNA(VLOOKUP(G4,'Machine Helper Sheet'!$B$2:$D$16,3,FALSE), IF(ISNUMBER(VLOOKUP(G4,$A$2:$I$200,9,FALSE)), VLOOKUP(G4,$A$2:$I$200,8,FALSE)+VLOOKUP(G4,$A$2:$I$200,9,FALSE), 0 ) ) ) -> Tier | I4: 1T
A5: Assembling Line | B5: 1 | C5: 1 | D5: 1 | E5: Multi | F5: No | G5: Tier | H5: =IF(G5="Tier", "Tier", IFNA(VLOOKUP(G5,'Machine Helper Sheet'!$B$2:$D$16,3,FALSE), IF(ISNUMBER(VLOOKUP(G5,$A$2:$I$200,9,FALSE)), VLOOKUP(G5,$A$2:$I$200,8,FALSE)+VLOOKUP(G5,$A$2:$I$200,9,FALSE), 0 ) ) ) -> Tier | I5: 10000000
A6: Assembling Machine | B6: 1 | C6: 1 | D6: 1 | E6: Single | F6: No | G6: Tier | H6: =IF(G6="Tier", "Tier", IFNA(VLOOKUP(G6,'Machine Helper Sheet'!$B$2:$D$16,3,FALSE), IF(ISNUMBER(VLOOKUP(G6,$A$2:$I$200,9,FALSE)), VLOOKUP(G6,$A$2:$I$200,8,FALSE)+VLOOKUP(G6,$A$2:$I$200,9,FALSE), 0 ) ) ) -> Tier | I6: 2T
A7: Autoclave | B7: 1 | C7: 1 | D7: 1 | E7: Single | F7: No | G7: Tier | H7: =IF(G7="Tier", "Tier", IFNA(VLOOKUP(G7,'Machine Helper Sheet'!$B$2:$D$16,3,FALSE), IF(ISNUMBER(VLOOKUP(G7,$A$2:$I$200,9,FALSE)), VLOOKUP(G7,$A$2:$I$200,8,FALSE)+VLOOKUP(G7,$A$2:$I$200,9,FALSE), 0 ) ) ) -> Tier | I7: 1T
A8: Bending Machine | B8: 1 | C8: 1 | D8: 1 | E8: Single | F8: No | G8: Tier | H8: =IF(G8="Tier", "Tier", IFNA(VLOOKUP(G8,'Machine Helper Sheet'!$B$2:$D$16,3,FALSE), IF(ISNUMBER(VLOOKUP(G8,$A$2:$I$200,9,FALSE)), VLOOKUP(G8,$A$2:$I$200,8,FALSE)+VLOOKUP(G8,$A$2:$I$200,9,FALSE), 0 ) ) ) -> Tier | I8: 1T
A9: Brewery | B9: 1 | C9: 1 | D9: 1 | E9: Single | F9: No | G9: Tier | H9: =IF(G9="Tier", "Tier", IFNA(VLOOKUP(G9,'Machine Helper Sheet'!$B$2:$D$16,3,FALSE), IF(ISNUMBER(VLOOKUP(G9,$A$2:$I$200,9,FALSE)), VLOOKUP(G9,$A$2:$I$200,8,FALSE)+VLOOKUP(G9,$A$2:$I$200,9,FALSE), 0 ) ) ) -> Tier | I9: 1T
A10: Canning Machine | B10: 1 | C10: 1 | D10: 1 | E10: Single | F10: No | G10: Tier | H10: =IF(G10="Tier", "Tier", IFNA(VLOOKUP(G10,'Machine Helper Sheet'!$B$2:$D$16,3,FALSE), IF(ISNUMBER(VLOOKUP(G10,$A$2:$I$200,9,FALSE)), VLOOKUP(G10,$A$2:$I$200,8,FALSE)+VLOOKUP(G10,$A$2:$I$200,9,FALSE), 0 ) ) ) -> Tier | I10: 1T
A11: Centrifuge | B11: 1 | C11: 1 | D11: 1 | E11: Single | F11: No | G11: Tier | H11: =IF(G11="Tier", "Tier", IFNA(VLOOKUP(G11,'Machine Helper Sheet'!$B$2:$D$16,3,FALSE), IF(ISNUMBER(VLOOKUP(G11,$A$2:$I$200,9,FALSE)), VLOOKUP(G11,$A$2:$I$200,8,FALSE)+VLOOKUP(G11,$A$2:$I$200,9,FALSE), 0 ) ) ) -> Tier | I11: 1T
A12: Chemical Bath | B12: 1 | C12: 1 | D12: 1 | E12: Single | F12: No | G12: Tier | H12: =IF(G12="Tier", "Tier", IFNA(VLOOKUP(G12,'Machine Helper Sheet'!$B$2:$D$16,3,FALSE), IF(ISNUMBER(VLOOKUP(G12,$A$2:$I$200,9,FALSE)), VLOOKUP(G12,$A$2:$I$200,8,FALSE)+VLOOKUP(G12,$A$2:$I$200,9,FALSE), 0 ) ) ) -> Tier | I12: 1T
A13: Chemical Reactor | B13: 1 | C13: 1 | D13: 1 | E13: Single | F13: No | G13: Tier | H13: =IF(G13="Tier", "Tier", IFNA(VLOOKUP(G13,'Machine Helper Sheet'!$B$2:$D$16,3,FALSE), IF(ISNUMBER(VLOOKUP(G13,$A$2:$I$200,9,FALSE)), VLOOKUP(G13,$A$2:$I$200,8,FALSE)+VLOOKUP(G13,$A$2:$I$200,9,FALSE), 0 ) ) ) -> Tier | I13: 1T
A14: Compressor | B14: 1 | C14: 1 | D14: 1 | E14: Single | F14: No | G14: Tier | H14: =IF(G14="Tier", "Tier", IFNA(VLOOKUP(G14,'Machine Helper Sheet'!$B$2:$D$16,3,FALSE), IF(ISNUMBER(VLOOKUP(G14,$A$2:$I$200,9,FALSE)), VLOOKUP(G14,$A$2:$I$200,8,FALSE)+VLOOKUP(G14,$A$2:$I$200,9,FALSE), 0 ) ) ) -> Tier | I14: 1T
A15: Cutting Machine | B15: 1 | C15: 1 | D15: 1 | E15: Single | F15: No | G15: Tier | H15: =IF(G15="Tier", "Tier", IFNA(VLOOKUP(G15,'Machine Helper Sheet'!$B$2:$D$16,3,FALSE), IF(ISNUMBER(VLOOKUP(G15,$A$2:$I$200,9,FALSE)), VLOOKUP(G15,$A$2:$I$200,8,FALSE)+VLOOKUP(G15,$A$2:$I$200,9,FALSE), 0 ) ) ) -> Tier | I15: 1T
A16: Cyclotron | B16: 1 | C16: 1 | D16: 1 | E16: Multi | F16: No | G16: Tier | H16: =IF(G16="Tier", "Tier", IFNA(VLOOKUP(G16,'Machine Helper Sheet'!$B$2:$D$16,3,FALSE), IF(ISNUMBER(VLOOKUP(G16,$A$2:$I$200,9,FALSE)), VLOOKUP(G16,$A$2:$I$200,8,FALSE)+VLOOKUP(G16,$A$2:$I$200,9,FALSE), 0 ) ) ) -> Tier | I16: 1T
A17: Dehydrator | B17: 1 | C17: 1 | D17: 1 | E17: Single | F17: No | G17: Tier | H17: =IF(G17="Tier", "Tier", IFNA(VLOOKUP(G17,'Machine Helper Sheet'!$B$2:$D$16,3,FALSE), IF(ISNUMBER(VLOOKUP(G17,$A$2:$I$200,9,FALSE)), VLOOKUP(G17,$A$2:$I$200,8,FALSE)+VLOOKUP(G17,$A$2:$I$200,9,FALSE), 0 ) ) ) -> Tier | I17: 1T
... A19: Distillery | B19: 1 | C19: 1 | D19: 1 | E19: Single | F19: No | G19: Tier | H19: =IF(G19="Tier", "Tier", IFNA(VLOOKUP(G19,'Machine Helper Sheet'!$B$2:$D$16,3,FALSE), IF(ISNUMBER(VLOOKUP(G19,$A$2:$I$200,9,FALSE)), VLOOKUP(G19,$A$2:$I$200,8,FALSE)+VLOOKUP(G19,$A$2:$I$200,9,FALSE), 0 ) ) ) -> Tier | I19: 1T
A20: EBF | B20: 1 | C20: 1 | D20: 1 | E20: Multi | F20: No | G20: Tier | H20: =IF(G20="Tier", "Tier", IFNA(VLOOKUP(G20,'Machine Helper Sheet'!$B$2:$D$16,3,FALSE), IF(ISNUMBER(VLOOKUP(G20,$A$2:$I$200,9,FALSE)), VLOOKUP(G20,$A$2:$I$200,8,FALSE)+VLOOKUP(G20,$A$2:$I$200,9,FALSE), 0 ) ) ) -> Tier | I20: 1000
A21: Electric Furnace | B21: 1 | C21: 1 | D21: 1 | E21: Single | F21: No | G21: Tier | H21: =IF(G21="Tier", "Tier", IFNA(VLOOKUP(G21,'Machine Helper Sheet'!$B$2:$D$16,3,FALSE), IF(ISNUMBER(VLOOKUP(G21,$A$2:$I$200,9,FALSE)), VLOOKUP(G21,$A$2:$I$200,8,FALSE)+VLOOKUP(G21,$A$2:$I$200,9,FALSE), 0 ) ) ) -> Tier | I21: 1T
A22: Electrolyzer | B22: 1 | C22: 1 | D22: 1 | E22: Single | F22: No | G22: Tier | H22: =IF(G22="Tier", "Tier", IFNA(VLOOKUP(G22,'Machine Helper Sheet'!$B$2:$D$16,3,FALSE), IF(ISNUMBER(VLOOKUP(G22,$A$2:$I$200,9,FALSE)), VLOOKUP(G22,$A$2:$I$200,8,FALSE)+VLOOKUP(G22,$A$2:$I$200,9,FALSE), 0 ) ) ) -> Tier | I22: 1T
A23: Electromagnetic Separator | B23: 1 | C23: 1 | D23: 1 | E23: Single | F23: No | G23: Tier | H23: =IF(G23="Tier", "Tier", IFNA(VLOOKUP(G23,'Machine Helper Sheet'!$B$2:$D$16,3,FALSE), IF(ISNUMBER(VLOOKUP(G23,$A$2:$I$200,9,FALSE)), VLOOKUP(G23,$A$2:$I$200,8,FALSE)+VLOOKUP(G23,$A$2:$I$200,9,FALSE), 0 ) ) ) -> Tier | I23: 1T
A24: Extractor | B24: 1 | C24: 1 | D24: 1 | E24: Single | F24: No | G24: Tier | H24: =IF(G24="Tier", "Tier", IFNA(VLOOKUP(G24,'Machine Helper Sheet'!$B$2:$D$16,3,FALSE), IF(ISNUMBER(VLOOKUP(G24,$A$2:$I$200,9,FALSE)), VLOOKUP(G24,$A$2:$I$200,8,FALSE)+VLOOKUP(G24,$A$2:$I$200,9,FALSE), 0 ) ) ) -> Tier | I24: 1T
A25: Extruder | B25: 1 | C25: 1 | D25: 1 | E25: Single | F25: No | G25: Tier | H25: =IF(G25="Tier", "Tier", IFNA(VLOOKUP(G25,'Machine Helper Sheet'!$B$2:$D$16,3,FALSE), IF(ISNUMBER(VLOOKUP(G25,$A$2:$I$200,9,FALSE)), VLOOKUP(G25,$A$2:$I$200,8,FALSE)+VLOOKUP(G25,$A$2:$I$200,9,FALSE), 0 ) ) ) -> Tier | I25: 1T
A26: Fermenter | B26: 1 | C26: 1 | D26: 1 | E26: Single | F26: No | G26: Tier | H26: =IF(G26="Tier", "Tier", IFNA(VLOOKUP(G26,'Machine Helper Sheet'!$B$2:$D$16,3,FALSE), IF(ISNUMBER(VLOOKUP(G26,$A$2:$I$200,9,FALSE)), VLOOKUP(G26,$A$2:$I$200,8,FALSE)+VLOOKUP(G26,$A$2:$I$200,9,FALSE), 0 ) ) ) -> Tier | I26: 1T
A27: Fluid Canner | B27: 1 | C27: 1 | D27: 1 | E27: Single | F27: No | G27: Tier | H27: =IF(G27="Tier", "Tier", IFNA(VLOOKUP(G27,'Machine Helper Sheet'!$B$2:$D$16,3,FALSE), IF(ISNUMBER(VLOOKUP(G27,$A$2:$I$200,9,FALSE)), VLOOKUP(G27,$A$2:$I$200,8,FALSE)+VLOOKUP(G27,$A$2:$I$200,9,FALSE), 0 ) ) ) -> Tier | I27: 1T
A28: Fluid Extractor | B28: 1 | C28: 1 | D28: 1 | E28: Single | F28: No | G28: Tier | H28: =IF(G28="Tier", "Tier", IFNA(VLOOKUP(G28,'Machine Helper Sheet'!$B$2:$D$16,3,FALSE), IF(ISNUMBER(VLOOKUP(G28,$A$2:$I$200,9,FALSE)), VLOOKUP(G28,$A$2:$I$200,8,FALSE)+VLOOKUP(G28,$A$2:$I$200,9,FALSE), 0 ) ) ) -> Tier | I28: 1T
A29: Fluid Heater | B29: 1 | C29: 1 | D29: 1 | E29: Single | F29: No | G29: Tier | H29: =IF(G29="Tier", "Tier", IFNA(VLOOKUP(G29,'Machine Helper Sheet'!$B$2:$D$16,3,FALSE), IF(ISNUMBER(VLOOKUP(G29,$A$2:$I$200,9,FALSE)), VLOOKUP(G29,$A$2:$I$200,8,FALSE)+VLOOKUP(G29,$A$2:$I$200,9,FALSE), 0 ) ) ) -> Tier | I29: 1T
A30: Fluid Solidifier | B30: 1 | C30: 1 | D30: 1 | E30: Single | F30: No | G30: Tier | H30: =IF(G30="Tier", "Tier", IFNA(VLOOKUP(G30,'Machine Helper Sheet'!$B$2:$D$16,3,FALSE), IF(ISNUMBER(VLOOKUP(G30,$A$2:$I$200,9,FALSE)), VLOOKUP(G30,$A$2:$I$200,8,FALSE)+VLOOKUP(G30,$A$2:$I$200,9,FALSE), 0 ) ) ) -> Tier | I30: 1T
A31: Forge Hammer | B31: 1 | C31: 1 | D31: 1 | E31: Single | F31: No | G31: Tier | H31: =IF(G31="Tier", "Tier", IFNA(VLOOKUP(G31,'Machine Helper Sheet'!$B$2:$D$16,3,FALSE), IF(ISNUMBER(VLOOKUP(G31,$A$2:$I$200,9,FALSE)), VLOOKUP(G31,$A$2:$I$200,8,FALSE)+VLOOKUP(G31,$A$2:$I$200,9,FALSE), 0 ) ) ) -> Tier | I31: 1T
A32: Forming Press | B32: 1 | C32: 1 | D32: 1 | E32: Single | F32: No | G32: Tier | H32: =IF(G32="Tier", "Tier", IFNA(VLOOKUP(G32,'Machine Helper Sheet'!$B$2:$D$16,3,FALSE), IF(ISNUMBER(VLOOKUP(G32,$A$2:$I$200,9,FALSE)), VLOOKUP(G32,$A$2:$I$200,8,FALSE)+VLOOKUP(G32,$A$2:$I$200,9,FALSE), 0 ) ) ) -> Tier | I32: 1T
A33: GT++ 9-in-1 | B33: 2T | C33: 3.5 | D33: 0.8 | E33: Multi | F33: No | G33: Alloy Blast Smelter | H33: =IF(G33="Tier", "Tier", IFNA(VLOOKUP(G33,'Machine Helper Sheet'!$B$2:$D$16,3,FALSE), IF(ISNUMBER(VLOOKUP(G33,$A$2:$I$200,9,FALSE)), VLOOKUP(G33,$A$2:$I$200,8,FALSE)+VLOOKUP(G33,$A$2:$I$200,9,FALSE), 0 ) ) ) -> 1405511 | I33: 1000000
A34: GT++ Alloy Smelter Multi | B34: 1T*C | C34: 1 + 0.05C | D34: 1 | E34: Multi | F34: No | G34: Alloy Blast Smelter | H34: =IF(G34="Tier", "Tier", IFNA(VLOOKUP(G34,'Machine Helper Sheet'!$B$2:$D$16,3,FALSE), IF(ISNUMBER(VLOOKUP(G34,$A$2:$I$200,9,FALSE)), VLOOKUP(G34,$A$2:$I$200,8,FALSE)+VLOOKUP(G34,$A$2:$I$200,9,FALSE), 0 ) ) ) -> 1405511 | I34: 1T
A35: GT++ Bender/Press Multi | B35: 4T | C35: 6 | D35: 1 | E35: Multi | F35: No | G35: T1 Rocket | H35: =IF(G35="Tier", "Tier", IFNA(VLOOKUP(G35,'Machine Helper Sheet'!$B$2:$D$16,3,FALSE), IF(ISNUMBER(VLOOKUP(G35,$A$2:$I$200,9,FALSE)), VLOOKUP(G35,$A$2:$I$200,8,FALSE)+VLOOKUP(G35,$A$2:$I$200,9,FALSE), 0 ) ) ) -> 105511 | I35: 40000
A36: GT++ Centrifuge Multi | B36: 6T | C36: 2.25 | D36: 0.9 | E36: Multi | F36: No | G36: T1 Rocket | H36: =IF(G36="Tier", "Tier", IFNA(VLOOKUP(G36,'Machine Helper Sheet'!$B$2:$D$16,3,FALSE), IF(ISNUMBER(VLOOKUP(G36,$A$2:$I$200,9,FALSE)), VLOOKUP(G36,$A$2:$I$200,8,FALSE)+VLOOKUP(G36,$A$2:$I$200,9,FALSE), 0 ) ) ) -> 105511 | I36: 25000
A37: GT++ Chisel Multi | B37: 16T | C37: 3 | D37: 0.75 | E37: Multi | F37: No | G37: Alloy Blast Smelter | H37: =IF(G37="Tier", "Tier", IFNA(VLOOKUP(G37,'Machine Helper Sheet'!$B$2:$D$16,3,FALSE), IF(ISNUMBER(VLOOKUP(G37,$A$2:$I$200,9,FALSE)), VLOOKUP(G37,$A$2:$I$200,8,FALSE)+VLOOKUP(G37,$A$2:$I$200,9,FALSE), 0 ) ) ) -> 1405511 | I37: 1T
A38: GT++ Coke Oven | B38: 24 | C38: 1 | D38: 0.75 | E38: Multi | F38: No | G38: Alloy Blast Smelter | H38: =IF(G38="Tier", "Tier", IFNA(VLOOKUP(G38,'Machine Helper Sheet'!$B$2:$D$16,3,FALSE), IF(ISNUMBER(VLOOKUP(G38,$A$2:$I$200,9,FALSE)), VLOOKUP(G38,$A$2:$I$200,8,FALSE)+VLOOKUP(G38,$A$2:$I$200,9,FALSE), 0 ) ) ) -> 1405511 | I38: 20000
A39: GT++ Cutting Machine Multi | B39: 4T | C39: 3 | D39: 0.75 | E39: Multi | F39: No | G39: Alloy Blast Smelter | H39: =IF(G39="Tier", "Tier", IFNA(VLOOKUP(G39,'Machine Helper Sheet'!$B$2:$D$16,3,FALSE), IF(ISNUMBER(VLOOKUP(G39,$A$2:$I$200,9,FALSE)), VLOOKUP(G39,$A$2:$I$200,8,FALSE)+VLOOKUP(G39,$A$2:$I$200,9,FALSE), 0 ) ) ) -> 1405511 | I39: 130000
A40: GT++ DT Tier 1 | B40: 4 | C40: 3.5 | D40: 1 | E40: Multi | F40: No | G40: Alloy Blast Smelter | H40: =IF(G40="Tier", "Tier", IFNA(VLOOKUP(G40,'Machine Helper Sheet'!$B$2:$D$16,3,FALSE), IF(ISNUMBER(VLOOKUP(G40,$A$2:$I$200,9,FALSE)), VLOOKUP(G40,$A$2:$I$200,8,FALSE)+VLOOKUP(G40,$A$2:$I$200,9,FALSE), 0 ) ) ) -> 1405511 | I40: 1T
A41: GT++ DT Tier 2 | B41: 12 | C41: 3.5 | D41: 1 | E41: Multi | F41: No | G41: Alloy Blast Smelter | H41: =IF(G41="Tier", "Tier", IFNA(VLOOKUP(G41,'Machine Helper Sheet'!$B$2:$D$16,3,FALSE), IF(ISNUMBER(VLOOKUP(G41,$A$2:$I$200,9,FALSE)), VLOOKUP(G41,$A$2:$I$200,8,FALSE)+VLOOKUP(G41,$A$2:$I$200,9,FALSE), 0 ) ) ) -> 1405511 | I41: 1T
...

Sheet Item Helper Sheet
A1: GT Tier | B1: Number | C1: Importance Numbers | D1: Rarity Numbers | E1: (This rarity value represents the expected amount produced/demanded by progression)
A2: 00 - ULV | B2: 0 | C2: 0 - No uses | D2: 0 - No real rarity/value | E2: (The values chosen are arbitrary, but the idea is that high rarity materials are hard to produce, and needed in small amounts compared to low rarity materials)
A3: 01 - LV | B3: 1 | C3: 1 - Unpopular side content uses | D3: 1 - 1000+ stacks
A4: 02 - MV | B4: 2 | C4: 2 - Popular side content uses | D4: 2 - 100 to 1000 stacks | E4: (An idea I had to measure if the material amounts in a processing line are reasonable is to multiply material tier by rarity)
A5: 03 - HV | B5: 3 | C5: 3 - Unpopular main content uses | D5: 3 - 10 to 100 stacks | E5: (Since GTNH numbers naturally escalate from tier to tier, multiplying like this could represent how material amounts should compare to each other, and automatically find which materials are the most important in each line)
A6: 04 - EV | B6: 4 | C6: 4 - Popular main content uses | D6: 4 - 1 to 10 stacks | E6: (As an example, if Sulfuric Acid and Osmium are produced in the same proportion in a processing line, Osmium becomes the main output, since it's higher tier and rarer)
A7: 05 - IV | B7: 5 | C7: 5 - Gates main progression | D7: 5 - Less than a stack
A8: 06 - LuV | B8: 6
A9: 07 - ZPM | B9: 7
A10: 08 - UV | B10: 8
A11: 09 - UHV | B11: 9
A12: 10 - UEV | B12: 10
A13: 11 - UIV | B13: 11
A14: 12 - UMV | B14: 12
A15: 13 - UXV | B15: 13
A16: 14 - MAX | B16: 14

Sheet Machine Helper Sheet
A1: GT Tier | B1: Machine Gate | C1: Cost Value | D1: Gate Machine Cost | G1: Coil Tier | H1: Tier Number | I1: GT Tier | J1: Max Heat Value | K1: Cost Value
A2: 00 - ULV | B2: ? | C2: =10^0 -> 1 | D2: =1 -> 1 | G2: 00 - None | H2: 0 | I2: N/A | J2: 0 | K2: 0
A3: 01 - LV | B3: Steam Turbine | C3: =10^1 -> 10 | D3: =10+D2 -> 11 | G3: 01 - Cupronickel | H3: 1 | I3: LV | J3: 1801 | K3: 10
A4: 02 - MV | B4: EBF | C4: =10^2 -> 100 | D4: =500+D3 -> 511 | G4: 02 - Kanthal | H4: 2 | I4: MV | J4: 2701 | K4: 40
A5: 03 - HV | B5: EBF (Kanthal) | C5: =10^3 -> 1000 | D5: =5000+D4 -> 5511 | G5: 03 - Nichrome | H5: 3 | I5: HV | J5: 3601 | K5: 200
A6: 04 - EV | B6: T1 Rocket | C6: =10^4 -> 10000 | D6: =100000+D5 -> 105511 | G6: 04 - TPV-Alloy | H6: 4 | I6: EV | J6: 4501 | K6: 6000
A7: 05 - IV | B7: T2 Rocket | C7: =10^5 -> 100000 | D7: =1000000+D6 -> 1105511 | G7: 05 - HSS-G | H7: 5 | I7: IV | J7: 5401 | K7: 30000
A8: 06 - LuV | B8: Assembling Line | C8: =10^6 -> 1000000 | D8: =10000000+D7 -> 11105511 | G8: 06 - HSS-S | H8: 6 | I8: IV | J8: 6301 | K8: 60000
A9: 07 - ZPM | B9: Fusion Reactor Mk1 | C9: =10^7 -> 10000000 | D9: =30000000+D8 -> 41105511 | G9: 07 - Naquadah | H9: 7 | I9: LuV | J9: 7201 | K9: 300000
A10: 08 - UV | B10: Fusion Reactor Mk2 | C10: =10^8 -> 100000000 | D10: =200000000+D9 -> 241105511 | G10: 08 - Naq Alloy | H10: 8 | I10: LuV | J10: 8101 | K10: 400000
A11: 09 - UHV | B11: Fusion Reactor Mk3 | C11: =10^9 -> 1000000000 | D11: =2000000000+D10 -> 2241105511 | G11: 09 - Trinium | H11: 9 | I11: ZPM | J11: 9001 | K11: 100000
A12: 10 - UEV | B12: ? | C12: =10^10 -> 10000000000 | G12: 10 - Elec Flux | H12: 10 | I12: UV | J12: 9901
A13: 11 - UIV | B13: ? | C13: =10^11 -> 100000000000 | G13: 11 - Awak Drac | H13: 11 | I13: UHV | J13: 10801
A14: 12 - UMV | B14: ? | C14: =10^12 -> 1000000000000 | G14: 12 - Infinity | H14: 12 | I14: UEV | J14: 11701
A15: 13 - UXV | B15: ? | C15: =10^13 -> 10000000000000 | G15: 13 - Hypogen | H15: 13 | I15: UIV | J15: 12601
A16: 14 - MAX | B16: ? | C16: =10^14 -> 100000000000000 | G16: 14 - Eternal | H16: 14 | I16: UMV | J16: 13501

Sheet Recipe Templates
A1: Recipes | B1: Inputs | C1: Input(L) | D1: Outputs | E1: Output(L) | F1: Machine Type | G1: Machine Nº | H1: Min Tier | I1: EU/t | J1: Time (t) | K1: EU Cost | L1: OC Tier | M1: OC EU/t | N1: OC Time (t) | O1: OC EU Cost
A3: 1 In/Out | F3: Chemical Reactor | G3: 1 | H3: 1 | I3: 16 | J3: 20 | K3: =I3*J3*G3 -> 320 | L3: 1 | M3: =I3*(2^((L3-H3)*2)) -> 16 | N3: =ROUNDUP(IF(F3="Chemical Reactor",J3/(2^((L3-H3)*2)),J3/(2^(L3-H3))),0) -> 20 | O3: =M3*N3*G3 -> 320
C4: 1000 | E4: 1000
A6: 2 In/Out | F6: Chemical Reactor | G6: 1 | H6: 1 | I6: 16 | J6: 20 | K6: =I6*J6*G6 -> 320 | L6: 1 | M6: =I6*(2^((L6-H6)*2)) -> 16 | N6: =ROUNDUP(IF(F6="Chemical Reactor",J6/(2^((L6-H6)*2)),J6/(2^(L6-H6))),0) -> 20 | O6: =M6*N6*G6 -> 320
C7: 1000 | E7: 1000
C8: 1000 | E8: 1000
A10: 3 In/Out | F10: Chemical Reactor | G10: 1 | H10: 1 | I10: 16 | J10: 20 | K10: =I10*J10*G10 -> 320 | L10: 1 | M10: =I10*(2^((L10-H10)*2)) -> 16 | N10: =ROUNDUP(IF(F10="Chemical Reactor",J10/(2^((L10-H10)*2)),J10/(2^(L10-H10))),0) -> 20 | O10: =M10*N10*G10 -> 320
C11: 1000 | E11: 1000
C12: 1000 | E12: 1000
C13: 1000 | E13: 1000

Sheet Template Recipe Line
A4: Recipes | B4: Inputs | C4: Input(L) | D4: Outputs | E4: Output(L) | F4: Machine Type | G4: Machine Count | H4: Min Tier | I4: EU/t | J4: Time (t) | K4: EU Cost | L4: OC Tier | M4: OC EU/t | N4: OC Time (t) | O4: OC EU Cost
A5: Recipe 1 | F5: Chemical Reactor | G5: 2 | H5: 1 | I5: 16 | J5: 20 | K5: =I5*J5*G5 -> 640 | L5: 3 | M5: =I5*(2^((L5-H5)*2)) -> 256 | N5: =ROUNDUP(IF(F5="Chemical Reactor",J5/(2^((L5-H5)*2)),J5/(2^(L5-H5))),0) -> 2 | O5: =M5*N5*G5 -> 1024
B6: Sulfuric Acid | C6: 500 | D6: Platinum | E6: 1000
B7: PTFE | C7: 600 | D7: Osmium | E7: 1000 | V7: Tier | W7: Importance | X7: Demand
B8: Polyethylene | C8: 2000 | V8: =VLOOKUP(T8,'Item List'!A2:D6,2,FALSE) -> #N/A | W8: =VLOOKUP(T8,'Item List'!A2:D6,3,FALSE) -> #N/A | X8: =VLOOKUP(T8,'Item List'!A2:D6,4,FALSE) -> #N/A
A9: Recipe 2 | F9: Mixer | G9: 3 | H9: 2 | I9: 120 | J9: 60 | K9: =I9*J9*G9 -> 21600 | L9: 12 | M9: =I9*(2^((L9-H9)*2)) -> 125829120 | N9: =ROUNDUP(IF(F9="Chemical Reactor",J9/(2^((L9-H9)*2)),J9/(2^(L9-H9))),0) -> 1 | O9: =M9*N9*G9 -> 377487360 | V9: =VLOOKUP(T9,'Item List'!A2:D6,2,FALSE) -> #N/A | W9: =VLOOKUP(T9,'Item List'!A2:D6,3,FALSE) -> #N/A | X9: =VLOOKUP(T9,'Item List'!A2:D6,4,FALSE) -> #N/A
B10: Osmium | C10: 500 | D10: Platinum | E10: 250 | V10: =VLOOKUP(T10,'Item List'!A2:D6,2,FALSE) -> #N/A | W10: =VLOOKUP(T10,'Item List'!A2:D6,3,FALSE) -> #N/A | X10: =VLOOKUP(T10,'Item List'!A2:D6,4,FALSE) -> #N/A
B11: PTFE | C11: 1000 | D11: Sulfuric Acid | E11: 1000 | V11: =VLOOKUP(T11,'Item List'!A2:D6,2,FALSE) -> #N/A | W11: =VLOOKUP(T11,'Item List'!A2:D6,3,FALSE) -> #N/A | X11: =VLOOKUP(T11,'Item List'!A2:D6,4,FALSE) -> #N/A
D12: Polyethylene | E12: 3000 | V12: =VLOOKUP(T12,'Item List'!A2:D6,2,FALSE) -> #N/A | W12: =VLOOKUP(T12,'Item List'!A2:D6,3,FALSE) -> #N/A | X12: =VLOOKUP(T12,'Item List'!A2:D6,4,FALSE) -> #N/A
B21: Platinum | D21: PTFE

Sheet Poly SI Silicon
B1: Line for Silicon Poly SI using Salt (NaCl) | V1: <- Recipes | X1: Line for Silicon Poly SI using Salt (NaCl)
B2: This line is all LV and uses Salt, which can be mined directly from OW ore, but the salt electrolysis takes up a lot of time and EU. | V2: Math -> | X2: This line is all LV and uses Salt, which can be mined directly from OW ore, but the salt electrolysis takes up a lot of time and EU.
B4: Recipes | C4: Inputs | D4: Input(L) | E4: Outputs | F4: Output(L) | H4: Machine Type | I4: Perfect OC | J4: Parallels | K4: Recipe Tier | L4: Tier Number | M4: EU/t | N4: Time (t) | O4: EU Cost | P4: OC Tier | Q4: OC Tier Number | R4: OC EU/t | S4: OC Time (t) | T4: OC EU Cost | AF4: Inputs | AG4: Amount Produced | AH4: Tier | AI4: Importance | AJ4: Rarity | AM4: Current Output/s | AO4: EU Cost per Output | AP4: EU Cost per Output OC
B5: 1: Silicon Tetrachloride | H5: Chemical Reactor | I5: No | J5: 1 | K5: 01 - LV | L5: =VLOOKUP(K5,'Item Helper Sheet'!A2:B16,2,FALSE) -> 1 | M5: 30 | N5: =ROUNDUP(20*20*I7/J5,0) -> 400 | O5: =M5*N5*J5 -> 12000 | P5: 02 - MV | Q5: =VLOOKUP(P5,'Item Helper Sheet'!A2:B16,2,FALSE) -> 2 | R5: =M5*(2^((Q5-L5)*2)) -> 120 | S5: =ROUNDUP(IF(I5="Yes",N5/(2^((Q5-L5)*2)),N5/(2^(Q5-L5))),0) -> 200 | T5: =R5*S5*J5 -> 24000 | AF5: Chlorine | AG5: 0 | AH5: =VLOOKUP(AF5,'Item List'!$A$2:$D$300,2,FALSE) -> 1 | AI5: =VLOOKUP(AF5,'Item List'!$A$2:$D$300,3,FALSE) -> 4 | AJ5: =VLOOKUP(AF5,'Item List'!$A$2:$D$300,4,FALSE) -> 1 | AM5: =AL11/AC17*20 -> 0.015625 | AO5: =Y16/AL11 -> 53400 | AP5: =Z16/AL11 -> 106800
C6: Raw Silicon Dust | D6: =1*I7 -> 1 | E6: Silicon Tetrachloride | F6: =1000*I7 -> 1000 | AF6: Raw Silicon Dust | AG6: -1 | AH6: =VLOOKUP(AF6,'Item List'!$A$2:$D$300,2,FALSE) -> 1 | AI6: =VLOOKUP(AF6,'Item List'!$A$2:$D$300,3,FALSE) -> 4 | AJ6: =VLOOKUP(AF6,'Item List'!$A$2:$D$300,4,FALSE) -> 1
C7: Chlorine | D7: =4000*I7 -> 4000 | H7: Recipe Mult. | I7: 1 | AF7: Salt | AG7: 0 | AH7: =VLOOKUP(AF7,'Item List'!$A$2:$D$300,2,FALSE) -> 1 | AI7: =VLOOKUP(AF7,'Item List'!$A$2:$D$300,3,FALSE) -> 4 | AJ7: =VLOOKUP(AF7,'Item List'!$A$2:$D$300,4,FALSE) -> 1 | AL7: Main Output | AM7: Current Output/s OC | AO7: Time Per Output | AP7: Time per Output OC
AF8: Silicon Poly SI | AG8: 1 | AH8: =VLOOKUP(AF8,'Item List'!$A$2:$D$300,2,FALSE) -> 1 | AI8: =VLOOKUP(AF8,'Item List'!$A$2:$D$300,3,FALSE) -> 5 | AJ8: =VLOOKUP(AF8,'Item List'!$A$2:$D$300,4,FALSE) -> 3 | AL8: Silicon Poly SI | AM8: =AL11/AD17*20 -> 0.03125 | AO8: =AC17/AL11 -> 1280 | AP8: =AD17/AL11 -> 640
B9: 2: Silicon Poly SI | H9: Chemical Reactor | I9: No | J9: 1 | K9: 01 - LV | L9: =VLOOKUP(K9,'Item Helper Sheet'!A2:B16,2,FALSE) -> 1 | M9: 30 | N9: =ROUNDUP(5*20*I11/J9,0) -> 100 | O9: =M9*N9*J9 -> 3000 | P9: 02 - MV | Q9: =VLOOKUP(P9,'Item Helper Sheet'!A2:B16,2,FALSE) -> 2 | R9: =M9*(2^((Q9-L9)*2)) -> 120 | S9: =ROUNDUP(IF(I9="Yes",N9/(2^((Q9-L9)*2)),N9/(2^(Q9-L9))),0) -> 50 | T9: =R9*S9*J9 -> 6000 | AF9: Silicon Tetrachloride | AG9: 0 | AH9: =VLOOKUP(AF9,'Item List'!$A$2:$D$300,2,FALSE) -> 1 | AI9: =VLOOKUP(AF9,'Item List'!$A$2:$D$300,3,FALSE) -> 4 | AJ9: =VLOOKUP(AF9,'Item List'!$A$2:$D$300,4,FALSE) -> 2
C10: Sodium Dust | D10: =4*I11 -> 4 | E10: Silicon Poly SI | F10: =1*I11 -> 1 | AF10: Sodium Dust | AG10: 0 | AH10: =VLOOKUP(AF10,'Item List'!$A$2:$D$300,2,FALSE) -> 1 | AI10: =VLOOKUP(AF10,'Item List'!$A$2:$D$300,3,FALSE) -> 4 | AJ10: =VLOOKUP(AF10,'Item List'!$A$2:$D$300,4,FALSE) -> 1 | AL10: Main Output Amount | AM10: Desired Output/s | AO10: Desired Time Per Output
C11: Silicon Tetrachloride | D11: =1000*I11 -> 1000 | E11: Salt | F11: =8*I11 -> 8 | H11: Recipe Mult. | I11: 1 | AL11: =VLOOKUP(AL8,E6:F15,2,FALSE) -> 1 | AM11: 1 | AO11: =1/AM11*20 -> 20
X12: Recipes | Y12: EU Cost | Z12: OC EU | AB12: Recipes | AC12: Time (t) | AD12: OC Time (t) | AF12: Recipes | AG12: TierMin | AH12: TierOC | AI12: Nº Overclocks
B13: 3: Salt Electrolysis | H13: Electrolyzer | I13: No | J13: 1 | K13: 01 - LV | L13: =VLOOKUP(K13,'Item Helper Sheet'!A2:B16,2,FALSE) -> 1 | M13: 30 | N13: =ROUNDUP(16*20*I15/J13,0) -> 1280 | O13: =M13*N13*J13 -> 38400 | P13: 02 - MV | Q13: =VLOOKUP(P13,'Item Helper Sheet'!A2:B16,2,FALSE) -> 2 | R13: =M13*(2^((Q13-L13)*2)) -> 120 | S13: =ROUNDUP(IF(I13="Yes",N13/(2^((Q13-L13)*2)),N13/(2^(Q13-L13))),0) -> 640 | T13: =R13*S13*J13 -> 76800 | X13: 1: Silicon Tetrachloride | Y13: 12000 | Z13: 24000 | AB13: 1: Silicon Tetrachloride | AC13: 400 | AD13: 200 | AF13: 1: Silicon Tetrachloride | AG13: 1 | AH13: 2 | AI13: 1 | AN13: Input Rate | AO13: Proportion Main Output | AP13: Input/s at Current Speed | AQ13: Input/s at Desired Speed
C14: Salt | D14: =2*I15 -> 8 | E14: Sodium Dust | F14: =1*I15 -> 4 | X14: 2: Silicon Poly SI | Y14: 3000 | Z14: 6000 | AB14: 2: Silicon Poly SI | AC14: 100 | AD14: 50 | AF14: 2: Silicon Poly SI | AG14: 1 | AH14: 2 | AI14: 1 | AN14: =VLOOKUP(AL14,X4:Y10,2) -> 1 | AO14: =AN14/$AL$11 -> 1 | AP14: =$AM$8*AO14 -> 0.03125 | AQ14: =$AM$11*AO14 -> 1
E15: Chlorine | F15: =1000*I15 -> 4000 | H15: Recipe Mult. | I15: 4 | X15: 3: Salt Electrolysis | Y15: 38400 | Z15: 76800 | AB15: 3: Salt Electrolysis | AC15: 1280 | AD15: 640 | AF15: 3: Salt Electrolysis | AG15: 1 | AH15: 2 | AI15: 1
X16: Grand Total | Y16: 53400 | Z16: 106800
C17: Silicon Poly SI | E17: Raw Silicon Dust
X18: SUM of Parallels | Y18: Machine Type
X19: Recipes | Y19: Chemical Reactor | Z19: Electrolyzer | AB19: SUM of Parallels | AC19: Recipe Tier | AF19: SUM of Parallels | AG19: OC Tier
X20: 1: Silicon Tetrachloride | Y20: 1 | AB20: Machine Type | AC20: 01 - LV | AD20: Grand Total | AF20: Machine Type | AG20: 02 - MV | AH20: Grand Total
X21: 2: Silicon Poly SI | Y21: 1 | AB21: Chemical Reactor | AC21: 2 | AD21: 2 | AF21: Chemical Reactor | AG21: 2 | AH21: 2
X22: 3: Salt Electrolysis | Z22: 1 | AB22: Electrolyzer | AC22: 1 | AD22: 1 | AF22: Electrolyzer | AG22: 1 | AH22: 1
X23: Grand Total | Y23: 2 | Z23: 1 | AB23: Grand Total | AC23: 3 | AD23: 3 | AF23: Grand Total | AG23: 3 | AH23: 3
B25: Line for Silicon Poly SI using Zinc Chloride (ZnCl₂) | V25: <- Recipes | X25: Line for Silicon Poly SI using Zinc Chloride (ZnCl₂)
B26: This line is the same as the one above but with Zinc Chloride instead of Salt. Zinc is harder to get, but it's recycled in this line. Longest recipe is 1/3 of the Salt line's longest, and total EU is less than 1/2. | V26: Math -> | X26: This line is the same as the one above but with Zinc Chloride instead of Salt. Zinc is harder to get, but it's recycled in this line. Longest recipe is 1/3 of the Salt line's longest, and total EU is less than 1/2.
B28: Recipes | C28: Inputs | D28: Input(L) | E28: Outputs | F28: Output(L) | H28: Machine Type | I28: Perfect OC | J28: Parallels | K28: Recipe Tier | L28: Tier Number | M28: EU/t | N28: Time (t) | O28: EU Cost | P28: OC Tier | Q28: OC Tier Number | R28: OC EU/t | S28: OC Time (t) | T28: OC EU Cost | AF28: Inputs | AG28: Amount Produced | AH28: Tier | AI28: Importance | AJ28: Rarity | AM28: Current Output/s | AO28: EU Cost per Output | AP28: EU Cost per Output OC
B29: 1: Silicon Tetrachloride | H29: Chemical Reactor | I29: No | J29: 1 | K29: 01 - LV | L29: =VLOOKUP(K29,'Item Helper Sheet'!A2:B16,2,FALSE) -> 1 | M29: 30 | N29: =ROUNDUP(20*20*I31/J29,0) -> 400 | O29: =M29*N29*J29 -> 12000 | P29: 02 - MV | Q29: =VLOOKUP(P29,'Item Helper Sheet'!A2:B16,2,FALSE) -> 2 | R29: =M29*(2^((Q29-L29)*2)) -> 120 | S29: =ROUNDUP(IF(I29="Yes",N29/(2^((Q29-L29)*2)),N29/(2^(Q29-L29))),0) -> 200 | T29: =R29*S29*J29 -> 24000 | AF29: Chlorine | AG29: 0 | AH29: =VLOOKUP(AF29,'Item List'!$A$2:$D$300,2,FALSE) -> 1 | AI29: =VLOOKUP(AF29,'Item List'!$A$2:$D$300,3,FALSE) -> 4 | AJ29: =VLOOKUP(AF29,'Item List'!$A$2:$D$300,4,FALSE) -> 1 | AM29: =AL35/AC41*20 -> 0.05 | AO29: =Y40/AL35 -> 27840 | AP29: =Z40/AL35 -> 51840
C30: Raw Silicon | D30: =1*I31 -> 1 | E30: Silicon Tetrachloride | F30: =1000*I31 -> 1000 | AF30: Raw Silicon | AG30: -1 | AH30: =VLOOKUP(AF30,'Item List'!$A$2:$D$300,2,FALSE) -> #N/A | AI30: =VLOOKUP(AF30,'Item List'!$A$2:$D$300,3,FALSE) -> #N/A | AJ30: =VLOOKUP(AF30,'Item List'!$A$2:$D$300,4,FALSE) -> #N/A
C31: Chlorine | D31: =4000*I31 -> 4000 | H31: Recipe Mult. | I31: 1 | AF31: Silicon Poly SI | AG31: 1 | AH31: =VLOOKUP(AF31,'Item List'!$A$2:$D$300,2,FALSE) -> 1 | AI31: =VLOOKUP(AF31,'Item List'!$A$2:$D$300,3,FALSE) -> 5 | AJ31: =VLOOKUP(AF31,'Item List'!$A$2:$D$300,4,FALSE) -> 3 | AL31: Main Output | AM31: Current Output/s OC | AO31: Time Per Output | AP31: Time per Output OC
AF32: Silicon Tetrachloride | AG32: 0 | AH32: =VLOOKUP(AF32,'Item List'!$A$2:$D$300,2,FALSE) -> 1 | AI32: =VLOOKUP(AF32,'Item List'!$A$2:$D$300,3,FALSE) -> 4 | AJ32: =VLOOKUP(AF32,'Item List'!$A$2:$D$300,4,FALSE) -> 2 | AL32: Silicon Poly SI | AM32: =AL35/AD41*20 -> 0.1 | AO32: =AC41/AL35 -> 400 | AP32: =AD41/AL35 -> 200
B33: 2: Silicon Poly SI | H33: Chemical Reactor | I33: No | J33: 1 | K33: 01 - LV | L33: =VLOOKUP(K33,'Item Helper Sheet'!A2:B16,2,FALSE) -> 1 | M33: 30 | N33: =ROUNDUP(20*20*I35/J33,0) -> 400 | O33: =M33*N33*J33 -> 12000 | P33: 02 - MV | Q33: =VLOOKUP(P33,'Item Helper Sheet'!A2:B16,2,FALSE) -> 2 | R33: =M33*(2^((Q33-L33)*2)) -> 120 | S33: =ROUNDUP(IF(I33="Yes",N33/(2^((Q33-L33)*2)),N33/(2^(Q33-L33))),0) -> 200 | T33: =R33*S33*J33 -> 24000 | AF33: Zinc | AG33: 0 | AH33: =VLOOKUP(AF33,'Item List'!$A$2:$D$300,2,FALSE) -> #N/A | AI33: =VLOOKUP(AF33,'Item List'!$A$2:$D$300,3,FALSE) -> #N/A | AJ33: =VLOOKUP(AF33,'Item List'!$A$2:$D$300,4,FALSE) -> #N/A
C34: Zinc | D34: =2*I35 -> 2 | E34: Silicon Poly SI | F34: =1*I35 -> 1 | AF34: Zinc Chloride | AG34: 0 | AH34: =VLOOKUP(AF34,'Item List'!$A$2:$D$300,2,FALSE) -> 2 | AI34: =VLOOKUP(AF34,'Item List'!$A$2:$D$300,3,FALSE) -> 4 | AJ34: =VLOOKUP(AF34,'Item List'!$A$2:$D$300,4,FALSE) -> 2 | AL34: Main Output Amount | AM34: Desired Output/s | AO34: Desired Time Per Output
C35: Silicon Tetrachloride | D35: =1000*I35 -> 1000 | E35: Zinc Chloride | F35: =6*I35 -> 6 | H35: Recipe Mult. | I35: 1 | AL35: =VLOOKUP(AL32,E28:F39,2,FALSE) -> 1 | AM35: 1 | AO35: =1/AM35*20 -> 20
X36: Recipes | Y36: EU Cost | Z36: OC EU Cost | AB36: Recipes | AC36: Time (t) | AD36: OC Time (t) | AF36: Recipes | AG36: TierMin | AH36: TierOC | AI36: Nº Overclocks
B37: 3: Zinc Chloride Electrolysis | H37: Electrolyzer | I37: No | J37: 1 | K37: 02 - MV | L37: =VLOOKUP(K37,'Item Helper Sheet'!A2:B16,2,FALSE) -> 2 | M37: 60 | N37: =ROUNDUP(1.6*20*I39/J37,0) -> 64 | O37: =M37*N37*J37 -> 3840 | P37: 02 - MV | Q37: =VLOOKUP(P37,'Item Helper Sheet'!A2:B16,2,FALSE) -> 2 | R37: =M37*(2^((Q37-L37)*2)) -> 60 | S37: =ROUNDUP(IF(I37="Yes",N37/(2^((Q37-L37)*2)),N37/(2^(Q37-L37))),0) -> 64 | T37: =R37*S37*J37 -> 3840 | X37: 1: Silicon Tetrachloride | Y37: 12000 | Z37: 24000 | AB37: 1: Silicon Tetrachloride | AC37: 400 | AD37: 200 | AF37: 1: Silicon Tetrachloride | AG37: 1 | AH37: 2 | AI37: 1 | AN37: Input Rate | AO37: Proportion Main Output | AP37: Input/s at Current Speed | AQ37: Input/s at Desired Speed
C38: Zinc Chloride | D38: =3*I39 -> 6 | E38: Zinc | F38: =1*I39 -> 2 | X38: 2: Silicon Poly SI | Y38: 12000 | Z38: 24000 | AB38: 2: Silicon Poly SI | AC38: 400 | AD38: 200 | AF38: 2: Silicon Poly SI | AG38: 1 | AH38: 2 | AI38: 1 | AN38: =VLOOKUP(AL38,X28:Y34,2) -> 1 | AO38: =AN38/$AL$11 -> 1 | AP38: =$AM$8*AO38 -> 0.03125 | AQ38: =$AM$11*AO38 -> 1
E39: Chlorine | F39: =2000*I39 -> 4000 | H39: Recipe Mult. | I39: 2 | X39: 3: Zinc Chloride Electrolysis | Y39: 3840 | Z39: 3840 | AB39: 3: Zinc Chloride Electrolysis | AC39: 64 | AD39: 64 | AF39: 3: Zinc Chloride Electrolysis | AG39: 2 | AH39: 2 | AI39: 0
X40: Grand Total | Y40: 27840 | Z40: 51840
C41: Silicon Poly SI | E41: Raw Silicon
X42: SUM of Parallels | Y42: Machine Type
X43: Recipes | Y43: Chemical Reactor | Z43: Electrolyzer | AB43: SUM of Parallels | AC43: Recipe Tier | AF43: SUM of Parallels | AG43: OC Tier
...

Sheet Diesel -> CBD
B1: Line for Diesel | BI1: <- Recipes | BK1: Line for Cetane-Boosted Diesel using Diesel
B2: This is the Diesel processing line for powergen. It's here to compared to CBD, to gauge if it's worth upgrading the fuel. | BI2: Math -> | BK2: This is the Diesel version of Cetane-Boosted Diesel, sourced from Oil processing with additives. The other option uses Biodiesel.
B4: Recipes | C4: Inputs | D4: Input(L) | E4: Outputs | F4: Output(L) | H4: Machine Type | I4: Mach. Cost Formula | J4: Energy Hatch Cost | K4: Machine Cost | L4: OC Energy Hatch Cost | M4: OC Machine Cost | N4: Mach. Start. Cost Form. | O4: Machine Start. Cost | P4: OC Machine Start. Cost | Q4: Parallel Formula | R4: Perfect OC | S4: Parallels | T4: Specific Parallels | U4: Actual Parallels | V4: OC Parallels | W4: Sp. OC Parallels | X4: Act. OC Parallels | Y4: Recipe Tier | Z4: Tier Number | AA4: Recipe EU/t | AB4: Recipe Time (t) | AC4: Mult. Time (t) | AD4: EU Cost | AF4: Base Tier | AG4: Machine Count | AH4: Amps per Machine | AI4: Total EU/t Input | AJ4: Possible Parallels | AK4: Total Parallels | AL4: Bonused EU/t | AM4: Consumed EU/t | AN4: Base Time (t) | AO4: Bonused Time (t) | AP4: Final Time (t) | AQ4: Final EU Cost | AS4: OC Tier | AT4: OC Tier Number | AU4: OC Mac. Count | AV4: OC Amps p/Machine | AW4: OC Total EU/t Input | AX4: OC Poss. Parallels | AY4: OC Total Parallels | AZ4: OC Starting EU/t | BA4: Post-Paral. OC | BB4: OC Machin. EU/t | BC4: OC Total EU/t | BD4: OC Base Time (t) | BE4: OC Bonus Time (t) | BF4: OC Final Time (t) | BG4: OC EU Cost
B5: 01: Oil DT Distillation | H5: Distillation Tower | I5: =VLOOKUP(H5,'Machine List'!$A$1:$I$300,9,FALSE) -> 4000+500(7O-5) | J5: =IF(VLOOKUP(H5,'Machine List'!$A$1:$I$300,5,FALSE)="Multi",IF(VLOOKUP(H5,'Machine List'!$A$1:$I$300,6,FALSE)="Yes",AG5*3*10^Z5,AG5*(2*3)*10^(Z5-1)),0) -> 600 | K5: =J5+IF(ISNUMBER(I5),I5, SWITCH( I5, "1T",1*10^Z5, "2T",2*10^Z5, "3T",3*10^Z5, "4T",4*10^Z5, "4000+500(7O-5)",4000+500*(7*I6-5), "13500 + 16C",13500+16*VLOOKUP(J7,'Machine Helper Sheet'!$G$1:$K$16,5,FALSE), 1 ) ) -> 19600 | L5: =IF(VLOOKUP(H5,'Machine List'!$A$1:$I$300,5,FALSE)="Multi",IF(VLOOKUP(H5,'Machine List'!$A$1:$I$300,6,FALSE)="Yes",AU5*3*10^AT5,AU5*(2*3)*10^(AT5-1)),0) -> 240000 | M5: =L5+IF(ISNUMBER(I5),I5, SWITCH( I5, "1T",1*10^AT5, "2T",2*10^AT5, "3T",3*10^AT5, "4T",4*10^AT5, "4000+500(7O-5)",4000+500*(7*I6-5), 1 ) ) -> 259000 | N5: =VLOOKUP(H5,'Machine List'!$A$1:$I$300,8,FALSE) -> Tier | O5: =IF(ISNUMBER(N5),N5,10^Z5) -> 1000 | P5: =IF(ISNUMBER(N5),N5,10^AT5) -> 100000 | Q5: =VLOOKUP(H5,'Machine List'!$A$1:$B$138,2,FALSE) -> 1 | R5: No | S5: =IF(ISNUMBER(Q5),Q5, SWITCH( Q5, "1",1, "2T",Z5*2, "4T",Z5*4, "6T",Z5*6, "8T",Z5*8, "10T",Z5*10, "12T",Z5*12, "14T",Z5*14, "16T",Z5*16, "2(T+1)",2*(Z5+1), "1T*C",Z5*J7, 1 ) ) -> 1 | T5: No | U5: =IF(OR(T5="No",T5=""),S5,T5) -> 1 | V5: =IF(ISNUMBER(Q5),Q5, SWITCH( Q5, "1",1, "2T",AT5*2, "4T",AT5*4, "6T",AT5*6, "8T",AT5*8, "10T",AT5*10, "12T",AT5*12, "14T",AT5*14, "16T",AT5*16, "2(T+1)",2*(AT5+1), "1T*C",AT5*J7, 1 ) ) -> 1 | W5: =T5 -> No | X5: =IF(OR(W5="No",W5=""),V5,W5) -> 1 | Y5: 03 - HV | Z5: =VLOOKUP(Y5,'Item Helper Sheet'!$A$2:$B$16,2,FALSE) -> 3 | AA5: 480 | AB5: =1.6*20 -> 32 | AC5: =AB5*I7 -> 19200 | AD5: =AA5*AC5 -> 9216000 | AF5: =Y5 -> 03 - HV | AG5: 1 | AH5: 1 | AI5: =AH5*8*4^Z5 -> 512 | AJ5: =MIN(ROUNDDOWN(AI5/AL5,0),U5) -> 1 | AK5: =AJ5*AG5 -> 1 | AL5: =ROUNDUP(AA5*VLOOKUP(H5,'Machine List'!$A$2:$D$219,4,FALSE),0) -> 480 | AM5: =AL5*AK5 -> 480 | AN5: =ROUNDUP(AB5*I7,0) -> 19200 | AO5: =ROUNDUP(AN5/VLOOKUP(H5,'Machine List'!$A$2:$D$219,3,FALSE),0) -> 19200 | AP5: =ROUNDUP(AO5/AK5,0) -> 19200 | AQ5: =AM5*AP5 -> 9216000 | AS5: 05 - IV | AT5: =VLOOKUP(AS5,'Item Helper Sheet'!$A$2:$B$16,2,FALSE) -> 5 | AU5: 4 | AV5: 1 | AW5: =AV5*8*4^AT5 -> 8192 | AX5: =MIN(ROUNDDOWN(AW5/AL5,0),X5) -> 1 | AY5: =AX5*AU5 -> 4 | AZ5: =AL5 -> 480 | BA5: =MIN(AT5-Z5,IF(AW5>=AZ6*4, IF(AW5>=AZ6*4^2, IF(AW5>=AZ6*4^3, IF(AW5>=AZ6*4^4, IF(AW5>=AZ6*4^5, IF(AW5>=AZ6*4^6, IF(AW5>=AZ6*4^7, IF(AW5>=AZ6*4^8, IF(AW5>=AZ6*4^9, IF(AW5>=AZ6*4^10, 9), 8), 7), 6), 5), 4), 3), 2), 1), 0)) -> 2 | BB5: =AZ5*AX5*4^BA5 -> 7680 | BC5: =BB5*AU5 -> 30720 | BD5: =ROUNDUP(IF(R5="Yes",AN5/(2^((BA5)*2)),AN5/(2^(BA5))),0) -> 4800 | BE5: =ROUNDUP(BD5/VLOOKUP(H5,'Machine List'!$A$2:$D$219,3,FALSE),0) -> 4800 | BF5: =ROUNDUP(BE5/AY5,0) -> 1200 | BG5: =BF5*BC5 -> 36864000 | BQ5: Inputs | BR5: Amount Produced | BS5: Tier | BT5: Importance | BU5: Rarity | BY5: Input Rate | BZ5: Proportion Main Output | CA5: Base Input/s | CB5: OC Input/s | CC5: Desired Input/s | CE5: Main Output | CF5: Output Amount | CG5: Current Output/s | CH5: Current Output/s OC | CI5: Desired Output/s
C6: Oil | D6: =500*I7 -> 300000 | E6: Sulfuric Gas | F6: =600*I7 -> 360000 | H6: Output Count | I6: {=match(TRUE,ISBLANK(F6:F18),0)-1} -> 5 | J6: Coil Tier | K6: Glass Tier | AZ6: =AZ5*AX5 -> 480 | BQ6: Diesel | BR6: 360000 | BS6: =VLOOKUP(BQ6,'Item List'!$A$2:$D$300,2,FALSE) -> 2 | BT6: =VLOOKUP(BQ6,'Item List'!$A$2:$D$300,3,FALSE) -> 4 | BU6: =VLOOKUP(BQ6,'Item List'!$A$2:$D$300,4,FALSE) -> 3 | BY6: =VLOOKUP(BW6,$BK$5:$BL$15,2) -> 134000 | BZ6: =BY6/$CF$21 -> 0.37222222 | CA6: =1/($CG$8/BZ6) -> 4.1666667 | CB6: =1/($CH$8/BZ6) -> 111.66667 | CC6: =1/($CI$8/BZ6) -> 372.22222 | CE6: Diesel | CF6: =VLOOKUP(CE6,BQ5:BR16,2,FALSE) -> 360000 | CG6: =CF21/BO31*20 -> 223.8806 | CH6: =CF21/BP31*20 -> 6000 | CI6: 1000
E7: Sulfuric Naphtha | F7: =200*I7 -> 120000 | H7: Recipe Mult. | I7: 600 | J7: 00 - None | K7: 0 | BQ7: Heavy Fuel | BR7: 20000 | BS7: =VLOOKUP(BQ7,'Item List'!$A$2:$D$300,2,FALSE) -> 1 | BT7: =VLOOKUP(BQ7,'Item List'!$A$2:$D$300,3,FALSE) -> 4 | BU7: =VLOOKUP(BQ7,'Item List'!$A$2:$D$300,4,FALSE) -> 2 | BY7: =VLOOKUP(BW7,$BK$5:$BL$15,2) -> 300000 | BZ7: =BY7/$CF$21 -> 0.83333333 | CA7: =1/($CG$8/BZ7) -> 9.3283582 | CB7: =1/($CH$8/BZ7) -> 250 | CC7: =1/($CI$8/BZ7) -> 833.33333 | CG7: Time Per Output | CH7: Time per Output OC | CI7: Desired Output Time
E8: Sulfuric Light Fuel | F8: =500*I7 -> 300000 | BQ8: Hydrogen | BR8: -134000 | BS8: =VLOOKUP(BQ8,'Item List'!$A$2:$D$300,2,FALSE) -> 1 | BT8: =VLOOKUP(BQ8,'Item List'!$A$2:$D$300,3,FALSE) -> 4 | BU8: =VLOOKUP(BQ8,'Item List'!$A$2:$D$300,4,FALSE) -> 1 | BY8: =VLOOKUP(BW8,$BK$5:$BL$15,2) -> 268000 | CG8: =BO31/CF6 -> 0.089333333 | CH8: =BP31/CF6 -> 0.0033333333 | CI8: =1/CI6 -> 0.001
E9: Sulfuric Heavy Fuel | F9: =150*I7 -> 90000 | BQ9: Hydrogen Sulfide | BR9: 0 | BS9: =VLOOKUP(BQ9,'Item List'!$A$2:$D$300,2,FALSE) -> 1 | BT9: =VLOOKUP(BQ9,'Item List'!$A$2:$D$300,3,FALSE) -> 4 | BU9: =VLOOKUP(BQ9,'Item List'!$A$2:$D$300,4,FALSE) -> 2 | CG9: EU Cost p/ Output | CH9: EU Cost p/ Output OC
E10: Naphthenic Acid | F10: =25*I7 -> 15000 | BQ10: Light Fuel | BR10: 0 | BS10: =VLOOKUP(BQ10,'Item List'!$A$2:$D$300,2,FALSE) -> 1 | BT10: =VLOOKUP(BQ10,'Item List'!$A$2:$D$300,3,FALSE) -> 4 | BU10: =VLOOKUP(BQ10,'Item List'!$A$2:$D$300,4,FALSE) -> 2 | BY10: Output Rate | BZ10: Proportion Main Output | CA10: Base Output/s | CB10: OC Output/s | CC10: Desired Output/s | CG10: =BL30/CF6 -> 31.173333 | CH10: =BM30/CF6 -> 107.99733
BQ11: Naphtha | BR11: 120000 | BS11: =VLOOKUP(BQ11,'Item List'!$A$2:$D$300,2,FALSE) -> 1 | BT11: =VLOOKUP(BQ11,'Item List'!$A$2:$D$300,3,FALSE) -> 4 | BU11: =VLOOKUP(BQ11,'Item List'!$A$2:$D$300,4,FALSE) -> 2 | BY11: =BX11 -> 360000 | BZ11: =BY11/$CF$21 -> 1 | CA11: =1/($CG$8/BZ11) -> 11.19403 | CB11: =1/($CH$8/BZ11) -> 300 | CC11: =1/($CI$8/BZ11) -> 1000
B12: 02: Gas Dessulfurizing | H12: LCR | I12: =VLOOKUP(H12,'Machine List'!$A$1:$I$300,9,FALSE) -> 4000 | J12: =IF(VLOOKUP(H12,'Machine List'!$A$1:$I$300,5,FALSE)="Multi",IF(VLOOKUP(H12,'Machine List'!$A$1:$I$300,6,FALSE)="Yes",AG12*3*10^Z12,AG12*(2*3)*10^(Z12-1)),0) -> 6 | K12: =J12+IF(ISNUMBER(I12),I12, SWITCH( I12, "1T",1*10^Z12, "2T",2*10^Z12, "3T",3*10^Z12, "4T",4*10^Z12, "4000+500(7O-5)",4000+500*(7*I13-5), "13500 + 16C",13500+16*VLOOKUP(J14,'Machine Helper Sheet'!$G$1:$K$16,5,FALSE), 1 ) ) -> 4006 | L12: =IF(VLOOKUP(H12,'Machine List'!$A$1:$I$300,5,FALSE)="Multi",IF(VLOOKUP(H12,'Machine List'!$A$1:$I$300,6,FALSE)="Yes",AU12*3*10^AT12,AU12*(2*3)*10^(AT12-1)),0) -> 60000 | M12: =L12+IF(ISNUMBER(I12),I12, SWITCH( I12, "1T",1*10^AT12, "2T",2*10^AT12, "3T",3*10^AT12, "4T",4*10^AT12, "4000+500(7O-5)",4000+500*(7*I13-5), 1 ) ) -> 64000 | N12: =VLOOKUP(H12,'Machine List'!$A$1:$I$300,8,FALSE) -> Tier | O12: =IF(ISNUMBER(N12),N12,10^Z12) -> 10 | P12: =IF(ISNUMBER(N12),N12,10^AT12) -> 100000 | Q12: =VLOOKUP(H12,'Machine List'!$A$1:$B$138,2,FALSE) -> 1 | R12: Yes | S12: =IF(ISNUMBER(Q12),Q12, SWITCH( Q12, "1",1, "2T",Z12*2, "4T",Z12*4, "6T",Z12*6, "8T",Z12*8, "10T",Z12*10, "12T",Z12*12, "14T",Z12*14, "16T",Z12*16, "2(T+1)",2*(Z12+1), "1T*C",Z12*J14, 1 ) ) -> 1 | T12: No | U12: =IF(OR(T12="No",T12=""),S12,T12) -> 1 | V12: =IF(ISNUMBER(Q12),Q12, SWITCH( Q12, "1",1, "2T",AT12*2, "4T",AT12*4, "6T",AT12*6, "8T",AT12*8, "10T",AT12*10, "12T",AT12*12, "14T",AT12*14, "16T",AT12*16, "2(T+1)",2*(AT12+1), "1T*C",AT12*J14, 1 ) ) -> 1 | W12: =T12 -> No | X12: =IF(OR(W12="No",W12=""),V12,W12) -> 1 | Y12: 01 - LV | Z12: =VLOOKUP(Y12,'Item Helper Sheet'!$A$2:$B$16,2,FALSE) -> 1 | AA12: 30 | AB12: =8*20 -> 160 | AC12: =AB12*I14 -> 3520 | AD12: =AA12*AC12 -> 105600 | AF12: =Y12 -> 01 - LV | AG12: 1 | AH12: 1 | AI12: =AH12*8*4^Z12 -> 32 | AJ12: =MIN(ROUNDDOWN(AI12/AL12,0),U12) -> 1 | AK12: =IF(OR(T12="No",T12=""),AG12*S12,AG12*T12) -> 1 | AL12: =ROUNDUP(AA12*VLOOKUP(H12,'Machine List'!$A$2:$D$219,4,FALSE),0) -> 30 | AM12: =AL12*AK12 -> 30 | AN12: =ROUNDUP(AB12*I14,0) -> 3520 | AO12: =ROUNDUP(AN12/VLOOKUP(H12,'Machine List'!$A$2:$D$219,3,FALSE),0) -> 3520 | AP12: =ROUNDUP(AO12/AK12,0) -> 3520 | AQ12: =AM12*AP12 -> 105600 | AS12: 05 - IV | AT12: =VLOOKUP(AS12,'Item Helper Sheet'!$A$2:$B$16,2,FALSE) -> 5 | AU12: =AG12 -> 1 | AV12: 1 | AW12: =AV12*8*4^AT12 -> 8192 | AX12: =MIN(ROUNDDOWN(AW12/AL12,0),X12) -> 1 | AY12: =AX12*AU12 -> 1 | AZ12: =AL12 -> 30 | BA12: =MIN(AT12-Z12,IF(AW12>=AZ13*4, IF(AW12>=AZ13*4^2, IF(AW12>=AZ13*4^3, IF(AW12>=AZ13*4^4, IF(AW12>=AZ13*4^5, IF(AW12>=AZ13*4^6, IF(AW12>=AZ13*4^7, IF(AW12>=AZ13*4^8, IF(AW12>=AZ13*4^9, IF(AW12>=AZ13*4^10, 9), 8), 7), 6), 5), 4), 3), 2), 1), 0)) -> 4 | BB12: =AZ12*AX12*4^BA12 -> 7680 | BC12: =BB12*AU12 -> 7680 | BD12: =ROUNDUP(IF(R12="Yes",AN12/(2^((BA12)*2)),AN12/(2^(BA12))),0) -> 14 | BE12: =ROUNDUP(BD12/VLOOKUP(H12,'Machine List'!$A$2:$D$219,3,FALSE),0) -> 14 | BF12: =ROUNDUP(BE12/AY12,0) -> 14 | BG12: =BF12*BC12 -> 107520 | BQ12: Naphthenic Acid | BR12: 15000 | BS12: =VLOOKUP(BQ12,'Item List'!$A$2:$D$300,2,FALSE) -> 3 | BT12: =VLOOKUP(BQ12,'Item List'!$A$2:$D$300,3,FALSE) -> 2 | BU12: =VLOOKUP(BQ12,'Item List'!$A$2:$D$300,4,FALSE) -> 2 | BY12: =BX12 -> 120000 | BZ12: =BY12/$CF$21 -> 0.33333333 | CA12: =1/($CG$8/BZ12) -> 3.7313433 | CB12: =1/($CH$8/BZ12) -> 100 | CC12: =1/($CI$8/BZ12) -> 333.33333 | CE12: Base Tier Recipes | CF12: Overclocked Recipes
C13: Sulfuric Gas | D13: =16000*I14 -> 352000 | E13: Refinery Gas | F13: =16000*I14 -> 352000 | H13: Output Count | I13: {=match(TRUE,ISBLANK(F13:F25),0)-1} -> 2 | J13: Coil Tier | K13: Glass Tier | AZ13: =AZ12*AX12 -> 30 | BQ13: Oil | BR13: -300000 | BS13: =VLOOKUP(BQ13,'Item List'!$A$2:$D$300,2,FALSE) -> 1 | BT13: =VLOOKUP(BQ13,'Item List'!$A$2:$D$300,3,FALSE) -> 4 | BU13: =VLOOKUP(BQ13,'Item List'!$A$2:$D$300,4,FALSE) -> 1 | BY13: =BX13 -> 352000 | BZ13: =BY13/$CF$21 -> 0.97777778 | CA13: =1/($CG$8/BZ13) -> 10.945274 | CB13: =1/($CH$8/BZ13) -> 293.33333 | CC13: =1/($CI$8/BZ13) -> 977.77778 | CE13: Total Machine Count | CF13: Total Machine Count
C14: Hydrogen | D14: =2000*I14 -> 44000 | E14: Hydrogen Sulfide | F14: =1000*I14 -> 22000 | H14: Recipe Mult. | I14: 22 | J14: 00 - None | K14: 0 | BQ14: Oxygen | BR14: -268000 | BS14: =VLOOKUP(BQ14,'Item List'!$A$2:$D$300,2,FALSE) -> 1 | BT14: =VLOOKUP(BQ14,'Item List'!$A$2:$D$300,3,FALSE) -> 5 | BU14: =VLOOKUP(BQ14,'Item List'!$A$2:$D$300,4,FALSE) -> 1 | BY14: =BX14 -> 67000 | BZ14: =BY14/$CF$21 -> 0.18611111 | CA14: =1/($CG$8/BZ14) -> 2.0833333 | CB14: =1/($CH$8/BZ14) -> 55.833333 | CC14: =1/($CI$8/BZ14) -> 186.11111 | CE14: =BR37 -> 7 | CF14: =BR43 -> 6
BQ15: Refinery Gas | BR15: 352000 | BS15: =VLOOKUP(BQ15,'Item List'!$A$2:$D$300,2,FALSE) -> 1 | BT15: =VLOOKUP(BQ15,'Item List'!$A$2:$D$300,3,FALSE) -> 4 | BU15: =VLOOKUP(BQ15,'Item List'!$A$2:$D$300,4,FALSE) -> 2 | CE15: Total Machine Cost | CF15: Total Machine Cost
B16: 03: Naphtha Dessulfurizing | H16: LCR | I16: =VLOOKUP(H16,'Machine List'!$A$1:$I$300,9,FALSE) -> 4000 | J16: =IF(VLOOKUP(H16,'Machine List'!$A$1:$I$300,5,FALSE)="Multi",IF(VLOOKUP(H16,'Machine List'!$A$1:$I$300,6,FALSE)="Yes",AG16*3*10^Z16,AG16*(2*3)*10^(Z16-1)),0) -> 6 | K16: =J16+IF(ISNUMBER(I16),I16, SWITCH( I16, "1T",1*10^Z16, "2T",2*10^Z16, "3T",3*10^Z16, "4T",4*10^Z16, "4000+500(7O-5)",4000+500*(7*I17-5), "13500 + 16C",13500+16*VLOOKUP(J18,'Machine Helper Sheet'!$G$1:$K$16,5,FALSE), 1 ) ) -> 4006 | L16: =IF(VLOOKUP(H16,'Machine List'!$A$1:$I$300,5,FALSE)="Multi",IF(VLOOKUP(H16,'Machine List'!$A$1:$I$300,6,FALSE)="Yes",AU16*3*10^AT16,AU16*(2*3)*10^(AT16-1)),0) -> 60000 | M16: =L16+IF(ISNUMBER(I16),I16, SWITCH( I16, "1T",1*10^AT16, "2T",2*10^AT16, "3T",3*10^AT16, "4T",4*10^AT16, "4000+500(7O-5)",4000+500*(7*I17-5), 1 ) ) -> 64000 | N16: =VLOOKUP(H16,'Machine List'!$A$1:$I$300,8,FALSE) -> Tier | O16: =IF(ISNUMBER(N16),N16,10^Z16) -> 10 | P16: =IF(ISNUMBER(N16),N16,10^AT16) -> 100000 | Q16: =VLOOKUP(H16,'Machine List'!$A$1:$B$138,2,FALSE) -> 1 | R16: Yes | S16: =IF(ISNUMBER(Q16),Q16, SWITCH( Q16, "1",1, "2T",Z16*2, "4T",Z16*4, "6T",Z16*6, "8T",Z16*8, "10T",Z16*10, "12T",Z16*12, "14T",Z16*14, "16T",Z16*16, "2(T+1)",2*(Z16+1), "1T*C",Z16*J18, 1 ) ) -> 1 | T16: No | U16: =IF(OR(T16="No",T16=""),S16,T16) -> 1 | V16: =IF(ISNUMBER(Q16),Q16, SWITCH( Q16, "1",1, "2T",AT16*2, "4T",AT16*4, "6T",AT16*6, "8T",AT16*8, "10T",AT16*10, "12T",AT16*12, "14T",AT16*14, "16T",AT16*16, "2(T+1)",2*(AT16+1), "1T*C",AT16*J18, 1 ) ) -> 1 | W16: =T16 -> No | X16: =IF(OR(W16="No",W16=""),V16,W16) -> 1 | Y16: 01 - LV | Z16: =VLOOKUP(Y16,'Item Helper Sheet'!$A$2:$B$16,2,FALSE) -> 1 | AA16: 30 | AB16: =8*20 -> 160 | AC16: =AB16*I18 -> 1600 | AD16: =AA16*AC16 -> 48000 | AF16: =Y16 -> 01 - LV | AG16: 1 | AH16: 1 | AI16: =AH16*8*4^Z16 -> 32 | AJ16: =MIN(ROUNDDOWN(AI16/AL16,0),U16) -> 1 | AK16: =IF(OR(T16="No",T16=""),AG16*S16,AG16*T16) -> 1 | AL16: =ROUNDUP(AA16*VLOOKUP(H16,'Machine List'!$A$2:$D$219,4,FALSE),0) -> 30 | AM16: =AL16*AK16 -> 30 | AN16: =ROUNDUP(AB16*I18,0) -> 1600 | AO16: =ROUNDUP(AN16/VLOOKUP(H16,'Machine List'!$A$2:$D$219,3,FALSE),0) -> 1600 | AP16: =ROUNDUP(AO16/AK16,0) -> 1600 | AQ16: =AM16*AP16 -> 48000 | AS16: 05 - IV | AT16: =VLOOKUP(AS16,'Item Helper Sheet'!$A$2:$B$16,2,FALSE) -> 5 | AU16: =AG16 -> 1 | AV16: 1 | AW16: =AV16*8*4^AT16 -> 8192 | AX16: =MIN(ROUNDDOWN(AW16/AL16,0),X16) -> 1 | AY16: =AX16*AU16 -> 1 | AZ16: =AL16 -> 30 | BA16: =MIN(AT16-Z16,IF(AW16>=AZ17*4, IF(AW16>=AZ17*4^2, IF(AW16>=AZ17*4^3, IF(AW16>=AZ17*4^4, IF(AW16>=AZ17*4^5, IF(AW16>=AZ17*4^6, IF(AW16>=AZ17*4^7, IF(AW16>=AZ17*4^8, IF(AW16>=AZ17*4^9, IF(AW16>=AZ17*4^10, 9), 8), 7), 6), 5), 4), 3), 2), 1), 0)) -> 4 | BB16: =AZ16*AX16*4^BA16 -> 7680 | BC16: =BB16*AU16 -> 7680 | BD16: =ROUNDUP(IF(R16="Yes",AN16/(2^((BA16)*2)),AN16/(2^(BA16))),0) -> 7 | BE16: =ROUNDUP(BD16/VLOOKUP(H16,'Machine List'!$A$2:$D$219,3,FALSE),0) -> 7 | BF16: =ROUNDUP(BE16/AY16,0) -> 7 | BG16: =BF16*BC16 -> 53760 | BQ16: Sulfuric Acid | BR16: 67000 | BS16: =VLOOKUP(BQ16,'Item List'!$A$2:$D$300,2,FALSE) -> 1 | BT16: =VLOOKUP(BQ16,'Item List'!$A$2:$D$300,3,FALSE) -> 4 | BU16: =VLOOKUP(BQ16,'Item List'!$A$2:$D$300,4,FALSE) -> 1 | CE16: =SUM(BZ23:BZ29) -> 44230 | CF16: =SUM(BZ34:BZ40) -> 1193200
C17: Sulfuric Naphtha | D17: =12000*I18 -> 120000 | E17: Naphtha | F17: =12000*I18 -> 120000 | H17: Output Count | I17: {=match(TRUE,ISBLANK(F17:F29),0)-1} -> 2 | J17: Coil Tier | K17: Glass Tier | AZ17: =AZ16*AX16 -> 30 | BQ17: Sulfuric Gas | BR17: 8000 | BS17: =VLOOKUP(BQ17,'Item List'!$A$2:$D$300,2,FALSE) -> 1 | BT17: =VLOOKUP(BQ17,'Item List'!$A$2:$D$300,3,FALSE) -> 4 | BU17: =VLOOKUP(BQ17,'Item List'!$A$2:$D$300,4,FALSE) -> 2 | CE17: Highest Starting Cost | CF17: Highest Starting Cost
C18: Hydrogen | D18: =2000*I18 -> 20000 | E18: Hydrogen Sulfide | F18: =1000*I18 -> 10000 | H18: Recipe Mult. | I18: 10 | J18: 00 - None | K18: 0 | BQ18: Sulfuric Heavy Fuel | BR18: 10000 | BS18: =VLOOKUP(BQ18,'Item List'!$A$2:$D$300,2,FALSE) -> 1 | BT18: =VLOOKUP(BQ18,'Item List'!$A$2:$D$300,3,FALSE) -> 4 | BU18: =VLOOKUP(BQ18,'Item List'!$A$2:$D$300,4,FALSE) -> 2 | CE18: =CA31 -> 1000 | CF18: =CA42 -> 100000
BQ19: Sulfuric Light Fuel | BR19: 0 | BS19: =VLOOKUP(BQ19,'Item List'!$A$2:$D$300,2,FALSE) -> 1 | BT19: =VLOOKUP(BQ19,'Item List'!$A$2:$D$300,3,FALSE) -> 4 | BU19: =VLOOKUP(BQ19,'Item List'!$A$2:$D$300,4,FALSE) -> 2
B20: 04: Light Fuel Dessulfurizing | H20: LCR | I20: =VLOOKUP(H20,'Machine List'!$A$1:$I$300,9,FALSE) -> 4000 | J20: =IF(VLOOKUP(H20,'Machine List'!$A$1:$I$300,5,FALSE)="Multi",IF(VLOOKUP(H20,'Machine List'!$A$1:$I$300,6,FALSE)="Yes",AG20*3*10^Z20,AG20*(2*3)*10^(Z20-1)),0) -> 6 | K20: =J20+IF(ISNUMBER(I20),I20, SWITCH( I20, "1T",1*10^Z20, "2T",2*10^Z20, "3T",3*10^Z20, "4T",4*10^Z20, "4000+500(7O-5)",4000+500*(7*I21-5), "13500 + 16C",13500+16*VLOOKUP(J22,'Machine Helper Sheet'!$G$1:$K$16,5,FALSE), 1 ) ) -> 4006 | L20: =IF(VLOOKUP(H20,'Machine List'!$A$1:$I$300,5,FALSE)="Multi",IF(VLOOKUP(H20,'Machine List'!$A$1:$I$300,6,FALSE)="Yes",AU20*3*10^AT20,AU20*(2*3)*10^(AT20-1)),0) -> 600 | M20: =L20+IF(ISNUMBER(I20),I20, SWITCH( I20, "1T",1*10^AT20, "2T",2*10^AT20, "3T",3*10^AT20, "4T",4*10^AT20, "4000+500(7O-5)",4000+500*(7*I21-5), 1 ) ) -> 4600 | N20: =VLOOKUP(H20,'Machine List'!$A$1:$I$300,8,FALSE) -> Tier | O20: =IF(ISNUMBER(N20),N20,10^Z20) -> 10 | P20: =IF(ISNUMBER(N20),N20,10^AT20) -> 1000 | Q20: =VLOOKUP(H20,'Machine List'!$A$1:$B$138,2,FALSE) -> 1 | R20: Yes | S20: =IF(ISNUMBER(Q20),Q20, SWITCH( Q20, "1",1, "2T",Z20*2, "4T",Z20*4, "6T",Z20*6, "8T",Z20*8, "10T",Z20*10, "12T",Z20*12, "14T",Z20*14, "16T",Z20*16, "2(T+1)",2*(Z20+1), "1T*C",Z20*J22, 1 ) ) -> 1 | T20: No | U20: =IF(OR(T20="No",T20=""),S20,T20) -> 1 | V20: =IF(ISNUMBER(Q20),Q20, SWITCH( Q20, "1",1, "2T",AT20*2, "4T",AT20*4, "6T",AT20*6, "8T",AT20*8, "10T",AT20*10, "12T",AT20*12, "14T",AT20*14, "16T",AT20*16, "2(T+1)",2*(AT20+1), "1T*C",AT20*J22, 1 ) ) -> 1 | W20: =T20 -> No | X20: =IF(OR(W20="No",W20=""),V20,W20) -> 1 | Y20: 01 - LV | Z20: =VLOOKUP(Y20,'Item Helper Sheet'!$A$2:$B$16,2,FALSE) -> 1 | AA20: 30 | AB20: =8*20 -> 160 | AC20: =AB20*I22 -> 4000 | AD20: =AA20*AC20 -> 120000 | AF20: =Y20 -> 01 - LV | AG20: 1 | AH20: 1 | AI20: =AH20*8*4^Z20 -> 32 | AJ20: =MIN(ROUNDDOWN(AI20/AL20,0),U20) -> 1 | AK20: =IF(OR(T20="No",T20=""),AG20*S20,AG20*T20) -> 1 | AL20: =ROUNDUP(AA20*VLOOKUP(H20,'Machine List'!$A$2:$D$219,4,FALSE),0) -> 30 | AM20: =AL20*AK20 -> 30 | AN20: =ROUNDUP(AB20*I22,0) -> 4000 | AO20: =ROUNDUP(AN20/VLOOKUP(H20,'Machine List'!$A$2:$D$219,3,FALSE),0) -> 4000 | AP20: =ROUNDUP(AO20/AK20,0) -> 4000 | AQ20: =AM20*AP20 -> 120000 | AS20: 03 - HV | AT20: =VLOOKUP(AS20,'Item Helper Sheet'!$A$2:$B$16,2,FALSE) -> 3 | AU20: =AG20 -> 1 | AV20: 1 | AW20: =AV20*8*4^AT20 -> 512 | AX20: =MIN(ROUNDDOWN(AW20/AL20,0),X20) -> 1 | AY20: =AX20*AU20 -> 1 | AZ20: =AL20 -> 30 | BA20: =MIN(AT20-Z20,IF(AW20>=AZ21*4, IF(AW20>=AZ21*4^2, IF(AW20>=AZ21*4^3, IF(AW20>=AZ21*4^4, IF(AW20>=AZ21*4^5, IF(AW20>=AZ21*4^6, IF(AW20>=AZ21*4^7, IF(AW20>=AZ21*4^8, IF(AW20>=AZ21*4^9, IF(AW20>=AZ21*4^10, 9), 8), 7), 6), 5), 4), 3), 2), 1), 0)) -> 2 | BB20: =AZ20*AX20*4^BA20 -> 480 | BC20: =BB20*AU20 -> 480 | BD20: =ROUNDUP(IF(R20="Yes",AN20/(2^((BA20)*2)),AN20/(2^(BA20))),0) -> 250 | BE20: =ROUNDUP(BD20/VLOOKUP(H20,'Machine List'!$A$2:$D$219,3,FALSE),0) -> 250 | BF20: =ROUNDUP(BE20/AY20,0) -> 250 | BG20: =BF20*BC20 -> 120000 | BQ20: Sulfuric Naphtha | BR20: 0 | BS20: =VLOOKUP(BQ20,'Item List'!$A$2:$D$300,2,FALSE) -> 1 | BT20: =VLOOKUP(BQ20,'Item List'!$A$2:$D$300,3,FALSE) -> 4 | BU20: =VLOOKUP(BQ20,'Item List'!$A$2:$D$300,4,FALSE) -> 2 | CE20: Fuel Type | CF20: Output Amount | CG20: Fuel Value/L | CH20: Generator Efficiency
C21: Sulfuric Light Fuel | D21: =12000*I22 -> 300000 | E21: Light Fuel | F21: =12000*I22 -> 300000 | H21: Output Count | I21: {=match(TRUE,ISBLANK(F21:F33),0)-1} -> 2 | J21: Coil Tier | K21: Glass Tier | AZ21: =AZ20*AX20 -> 30 | CE21: =CE6 -> Diesel | CF21: =CF6 -> 360000 | CG21: 480 | CH21: 1.5
C22: Hydrogen | D22: =2000*I22 -> 50000 | E22: Hydrogen Sulfide | F22: =1000*I22 -> 25000 | H22: Recipe Mult. | I22: 25 | J22: 00 - None | K22: 0 | BK22: Recipes | BL22: EU Cost | BM22: OC EU Cost | BN22: Recipes | BO22: Time (t) | BP22: OC Time (t) | BQ22: Recipes | BR22: TierMin | BS22: SUM of OC Tier Number | BT22: SUM of Post-Paral. OC | BY22: Recipes | BZ22: Machine Cost p/ Recipe | CA22: Machine Start. Cost
BK23: 01: Oil DT Distillation | BL23: 9216000 | BM23: 36864000 | BN23: 01: Oil DT Distillation | BO23: 19200 | BP23: 1200 | BQ23: 01: Oil DT Distillation | BR23: 3 | BS23: 5 | BT23: 2 | BY23: 01: Oil DT Distillation | BZ23: 19600 | CA23: 1000 | CE23: Energy Produced | CF23: Energy Consumed (OC) | CG23: Line EU Efficiency
B24: 05: Heavy Fuel Dessulfurizing | H24: LCR | I24: =VLOOKUP(H24,'Machine List'!$A$1:$I$300,9,FALSE) -> 4000 | J24: =IF(VLOOKUP(H24,'Machine List'!$A$1:$I$300,5,FALSE)="Multi",IF(VLOOKUP(H24,'Machine List'!$A$1:$I$300,6,FALSE)="Yes",AG24*3*10^Z24,AG24*(2*3)*10^(Z24-1)),0) -> 6 | K24: =J24+IF(ISNUMBER(I24),I24, SWITCH( I24, "1T",1*10^Z24, "2T",2*10^Z24, "3T",3*10^Z24, "4T",4*10^Z24, "4000+500(7O-5)",4000+500*(7*I25-5), "13500 + 16C",13500+16*VLOOKUP(J26,'Machine Helper Sheet'!$G$1:$K$16,5,FALSE), 1 ) ) -> 4006 | L24: =IF(VLOOKUP(H24,'Machine List'!$A$1:$I$300,5,FALSE)="Multi",IF(VLOOKUP(H24,'Machine List'!$A$1:$I$300,6,FALSE)="Yes",AU24*3*10^AT24,AU24*(2*3)*10^(AT24-1)),0) -> 600 | M24: =L24+IF(ISNUMBER(I24),I24, SWITCH( I24, "1T",1*10^AT24, "2T",2*10^AT24, "3T",3*10^AT24, "4T",4*10^AT24, "4000+500(7O-5)",4000+500*(7*I25-5), 1 ) ) -> 4600 | N24: =VLOOKUP(H24,'Machine List'!$A$1:$I$300,8,FALSE) -> Tier | O24: =IF(ISNUMBER(N24),N24,10^Z24) -> 10 | P24: =IF(ISNUMBER(N24),N24,10^AT24) -> 1000 | Q24: =VLOOKUP(H24,'Machine List'!$A$1:$B$138,2,FALSE) -> 1 | R24: Yes | S24: =IF(ISNUMBER(Q24),Q24, SWITCH( Q24, "1",1, "2T",Z24*2, "4T",Z24*4, "6T",Z24*6, "8T",Z24*8, "10T",Z24*10, "12T",Z24*12, "14T",Z24*14, "16T",Z24*16, "2(T+1)",2*(Z24+1), "1T*C",Z24*J26, 1 ) ) -> 1 | T24: No | U24: =IF(OR(T24="No",T24=""),S24,T24) -> 1 | V24: =IF(ISNUMBER(Q24),Q24, SWITCH( Q24, "1",1, "2T",AT24*2, "4T",AT24*4, "6T",AT24*6, "8T",AT24*8, "10T",AT24*10, "12T",AT24*12, "14T",AT24*14, "16T",AT24*16, "2(T+1)",2*(AT24+1), "1T*C",AT24*J26, 1 ) ) -> 1 | W24: =T24 -> No | X24: =IF(OR(W24="No",W24=""),V24,W24) -> 1 | Y24: 01 - LV | Z24: =VLOOKUP(Y24,'Item Helper Sheet'!$A$2:$B$16,2,FALSE) -> 1 | AA24: 30 | AB24: =8*20 -> 160 | AC24: =AB24*I26 -> 1600 | AD24: =AA24*AC24 -> 48000 | AF24: =Y24 -> 01 - LV | AG24: 1 | AH24: 1 | AI24: =AH24*8*4^Z24 -> 32 | AJ24: =MIN(ROUNDDOWN(AI24/AL24,0),U24) -> 1 | AK24: =IF(OR(T24="No",T24=""),AG24*S24,AG24*T24) -> 1 | AL24: =ROUNDUP(AA24*VLOOKUP(H24,'Machine List'!$A$2:$D$219,4,FALSE),0) -> 30 | AM24: =AL24*AK24 -> 30 | AN24: =ROUNDUP(AB24*I26,0) -> 1600 | AO24: =ROUNDUP(AN24/VLOOKUP(H24,'Machine List'!$A$2:$D$219,3,FALSE),0) -> 1600 | AP24: =ROUNDUP(AO24/AK24,0) -> 1600 | AQ24: =AM24*AP24 -> 48000 | AS24: 03 - HV | AT24: =VLOOKUP(AS24,'Item Helper Sheet'!$A$2:$B$16,2,FALSE) -> 3 | AU24: =AG24 -> 1 | AV24: 1 | AW24: =AV24*8*4^AT24 -> 512 | AX24: =MIN(ROUNDDOWN(AW24/AL24,0),X24) -> 1 | AY24: =AX24*AU24 -> 1 | AZ24: =AL24 -> 30 | BA24: =MIN(AT24-Z24,IF(AW24>=AZ25*4, IF(AW24>=AZ25*4^2, IF(AW24>=AZ25*4^3, IF(AW24>=AZ25*4^4, IF(AW24>=AZ25*4^5, IF(AW24>=AZ25*4^6, IF(AW24>=AZ25*4^7, IF(AW24>=AZ25*4^8, IF(AW24>=AZ25*4^9, IF(AW24>=AZ25*4^10, 9), 8), 7), 6), 5), 4), 3), 2), 1), 0)) -> 2 | BB24: =AZ24*AX24*4^BA24 -> 480 | BC24: =BB24*AU24 -> 480 | BD24: =ROUNDUP(IF(R24="Yes",AN24/(2^((BA24)*2)),AN24/(2^(BA24))),0) -> 100 | BE24: =ROUNDUP(BD24/VLOOKUP(H24,'Machine List'!$A$2:$D$219,3,FALSE),0) -> 100 | BF24: =ROUNDUP(BE24/AY24,0) -> 100 | BG24: =BF24*BC24 -> 48000 | BK24: 02: Gas Dessulfurizing | BL24: 105600 | BM24: 107520 | BN24: 02: Gas Dessulfurizing | BO24: 3520 | BP24: 14 | BQ24: 02: Gas Dessulfurizing | BR24: 1 | BS24: 5 | BT24: 4 | BY24: 02: Gas Dessulfurizing | BZ24: 4006 | CA24: 10 | CE24: =CF21*CG21*CH21 -> 259200000 | CF24: =BM30 -> 38879040 | CG24: =1-(CF24/CE24) -> 0.8500037
C25: Sulfuric Heavy Fuel | D25: =8000*I26 -> 80000 | E25: Heavy Fuel | F25: =8000*I26 -> 80000 | H25: Output Count | I25: {=match(TRUE,ISBLANK(F25:F37),0)-1} -> 2 | J25: Coil Tier | K25: Glass Tier | AZ25: =AZ24*AX24 -> 30 | BK25: 03: Naphtha Dessulfurizing | BL25: 48000 | BM25: 53760 | BN25: 03: Naphtha Dessulfurizing | BO25: 1600 | BP25: 7 | BQ25: 03: Naphtha Dessulfurizing | BR25: 1 | BS25: 5 | BT25: 4 | BY25: 03: Naphtha Dessulfurizing | BZ25: 4006 | CA25: 10
C26: Hydrogen | D26: =2000*I26 -> 20000 | E26: Hydrogen Sulfide | F26: =1000*I26 -> 10000 | H26: Recipe Mult. | I26: 10 | J26: 00 - None | K26: 0 | BK26: 04: Light Fuel Dessulfurizing | BL26: 120000 | BM26: 120000 | BN26: 04: Light Fuel Dessulfurizing | BO26: 4000 | BP26: 250 | BQ26: 04: Light Fuel Dessulfurizing | BR26: 1 | BS26: 3 | BT26: 2 | BY26: 04: Light Fuel Dessulfurizing | BZ26: 4006 | CA26: 10 | CE26: Net Powergen | CF26: Max Recipe Time | CG26: Net Powergen/t
BK27: 05: Heavy Fuel Dessulfurizing | BL27: 48000 | BM27: 48000 | BN27: 05: Heavy Fuel Dessulfurizing | BO27: 1600 | BP27: 100 | BQ27: 05: Heavy Fuel Dessulfurizing | BR27: 1 | BS27: 3 | BT27: 2 | BY27: 05: Heavy Fuel Dessulfurizing | BZ27: 4006 | CA27: 10 | CE27: =CE24-CF24 -> 220320960 | CF27: =BP31 -> 1200 | CG27: =CE27/CF27 -> 183600.8
